<?xml version="1.0" ?>
<!-- =================================================================================== -->
<!-- |    This document was autogenerated by xacro from LegV5_URDF_Export.xacro        | -->
<!-- |    EDITING THIS FILE BY HAND IS NOT RECOMMENDED                                 | -->
<!-- =================================================================================== -->
<robot name="LegV5_URDF_Export">
  <material name="silver">
    <color rgba="0.700 0.700 0.700 1.000"/>
  </material>
  <transmission name="base_to_R1_tran">
    <type>transmission_interface/SimpleTransmission</type>
    <joint name="base_to_R1">
      <hardwareInterface>hardware_interface/EffortJointInterface</hardwareInterface>
    </joint>
    <actuator name="base_to_R1_actr">
      <hardwareInterface>hardware_interface/EffortJointInterface</hardwareInterface>
      <mechanicalReduction>1</mechanicalReduction>
    </actuator>
  </transmission>
  <transmission name="base_to_L1_tran">
    <type>transmission_interface/SimpleTransmission</type>
    <joint name="base_to_L1">
      <hardwareInterface>hardware_interface/EffortJointInterface</hardwareInterface>
    </joint>
    <actuator name="base_to_L1_actr">
      <hardwareInterface>hardware_interface/EffortJointInterface</hardwareInterface>
      <mechanicalReduction>1</mechanicalReduction>
    </actuator>
  </transmission>
  <transmission name="R1_to_R2_Rev_tran">
    <type>transmission_interface/SimpleTransmission</type>
    <joint name="R1_to_R2_Rev">
      <hardwareInterface>hardware_interface/EffortJointInterface</hardwareInterface>
    </joint>
    <actuator name="R1_to_R2_Rev_actr">
      <hardwareInterface>hardware_interface/EffortJointInterface</hardwareInterface>
      <mechanicalReduction>1</mechanicalReduction>
    </actuator>
  </transmission>
  <transmission name="L1_to_L2_Rev_tran">
    <type>transmission_interface/SimpleTransmission</type>
    <joint name="L1_to_L2_Rev">
      <hardwareInterface>hardware_interface/EffortJointInterface</hardwareInterface>
    </joint>
    <actuator name="L1_to_L2_Rev_actr">
      <hardwareInterface>hardware_interface/EffortJointInterface</hardwareInterface>
      <mechanicalReduction>1</mechanicalReduction>
    </actuator>
  </transmission>
  <transmission name="R2_to_R3_Rev_tran">
    <type>transmission_interface/SimpleTransmission</type>
    <joint name="R2_to_R3_Rev">
      <hardwareInterface>hardware_interface/EffortJointInterface</hardwareInterface>
    </joint>
    <actuator name="R2_to_R3_Rev_actr">
      <hardwareInterface>hardware_interface/EffortJointInterface</hardwareInterface>
      <mechanicalReduction>1</mechanicalReduction>
    </actuator>
  </transmission>
  <transmission name="L2_to_L3_Rev_tran">
    <type>transmission_interface/SimpleTransmission</type>
    <joint name="L2_to_L3_Rev">
      <hardwareInterface>hardware_interface/EffortJointInterface</hardwareInterface>
    </joint>
    <actuator name="L2_to_L3_Rev_actr">
      <hardwareInterface>hardware_interface/EffortJointInterface</hardwareInterface>
      <mechanicalReduction>1</mechanicalReduction>
    </actuator>
  </transmission>
  <transmission name="R3_to_R4_Rev_tran">
    <type>transmission_interface/SimpleTransmission</type>
    <joint name="R3_to_R4_Rev">
      <hardwareInterface>hardware_interface/EffortJointInterface</hardwareInterface>
    </joint>
    <actuator name="R3_to_R4_Rev_actr">
      <hardwareInterface>hardware_interface/EffortJointInterface</hardwareInterface>
      <mechanicalReduction>1</mechanicalReduction>
    </actuator>
  </transmission>
  <transmission name="L3_to_L4_Rev_tran">
    <type>transmission_interface/SimpleTransmission</type>
    <joint name="L3_to_L4_Rev">
      <hardwareInterface>hardware_interface/EffortJointInterface</hardwareInterface>
    </joint>
    <actuator name="L3_to_L4_Rev_actr">
      <hardwareInterface>hardware_interface/EffortJointInterface</hardwareInterface>
      <mechanicalReduction>1</mechanicalReduction>
    </actuator>
  </transmission>
  <transmission name="R4_to_R5_Rev_tran">
    <type>transmission_interface/SimpleTransmission</type>
    <joint name="R4_to_R5_Rev">
      <hardwareInterface>hardware_interface/EffortJointInterface</hardwareInterface>
    </joint>
    <actuator name="R4_to_R5_Rev_actr">
      <hardwareInterface>hardware_interface/EffortJointInterface</hardwareInterface>
      <mechanicalReduction>1</mechanicalReduction>
    </actuator>
  </transmission>
  <transmission name="L4_to_L5_Rev_tran">
    <type>transmission_interface/SimpleTransmission</type>
    <joint name="L4_to_L5_Rev">
      <hardwareInterface>hardware_interface/EffortJointInterface</hardwareInterface>
    </joint>
    <actuator name="L4_to_L5_Rev_actr">
      <hardwareInterface>hardware_interface/EffortJointInterface</hardwareInterface>
      <mechanicalReduction>1</mechanicalReduction>
    </actuator>
  </transmission>
  <transmission name="L4_to_L6_Rev_tran">
    <type>transmission_interface/SimpleTransmission</type>
    <joint name="L4_to_L6_Rev">
      <hardwareInterface>hardware_interface/EffortJointInterface</hardwareInterface>
    </joint>
    <actuator name="L4_to_L6_Rev_actr">
      <hardwareInterface>hardware_interface/EffortJointInterface</hardwareInterface>
      <mechanicalReduction>1</mechanicalReduction>
    </actuator>
  </transmission>
  <transmission name="R4_to_R11_Rev_tran">
    <type>transmission_interface/SimpleTransmission</type>
    <joint name="R4_to_R11_Rev">
      <hardwareInterface>hardware_interface/EffortJointInterface</hardwareInterface>
    </joint>
    <actuator name="R4_to_R11_Rev_actr">
      <hardwareInterface>hardware_interface/EffortJointInterface</hardwareInterface>
      <mechanicalReduction>1</mechanicalReduction>
    </actuator>
  </transmission>
  <transmission name="R6_to_R13_Rev_tran">
    <type>transmission_interface/SimpleTransmission</type>
    <joint name="R6_to_R13_Rev">
      <hardwareInterface>hardware_interface/EffortJointInterface</hardwareInterface>
    </joint>
    <actuator name="R6_to_R13_Rev_actr">
      <hardwareInterface>hardware_interface/EffortJointInterface</hardwareInterface>
      <mechanicalReduction>1</mechanicalReduction>
    </actuator>
  </transmission>
  <transmission name="L4_to_L11_Rev_tran">
    <type>transmission_interface/SimpleTransmission</type>
    <joint name="L4_to_L11_Rev">
      <hardwareInterface>hardware_interface/EffortJointInterface</hardwareInterface>
    </joint>
    <actuator name="L4_to_L11_Rev_actr">
      <hardwareInterface>hardware_interface/EffortJointInterface</hardwareInterface>
      <mechanicalReduction>1</mechanicalReduction>
    </actuator>
  </transmission>
  <transmission name="L6_to_L13_Rev_tran">
    <type>transmission_interface/SimpleTransmission</type>
    <joint name="L6_to_L13_Rev">
      <hardwareInterface>hardware_interface/EffortJointInterface</hardwareInterface>
    </joint>
    <actuator name="L6_to_L13_Rev_actr">
      <hardwareInterface>hardware_interface/EffortJointInterface</hardwareInterface>
      <mechanicalReduction>1</mechanicalReduction>
    </actuator>
  </transmission>
  <transmission name="R4_to_R6_Rev_tran">
    <type>transmission_interface/SimpleTransmission</type>
    <joint name="R4_to_R6_Rev">
      <hardwareInterface>hardware_interface/EffortJointInterface</hardwareInterface>
    </joint>
    <actuator name="R4_to_R6_Rev_actr">
      <hardwareInterface>hardware_interface/EffortJointInterface</hardwareInterface>
      <mechanicalReduction>1</mechanicalReduction>
    </actuator>
  </transmission>
  <gazebo>
    <plugin filename="libgazebo_ros_control.so" name="control"/>
  </gazebo>

  <link name="base_link">
    <inertial>
      <origin rpy="0 0 0" xyz="0.07501013530813437 0.2763022813484983 0.014561357910343003"/>
      <mass value="1.9604027818380299"/>
      <inertia ixx="0.002513" ixy="-0.0" ixz="0.0" iyy="0.020291" iyz="-0.000101" izz="0.018394"/>
    </inertial>
    <visual>
      <origin rpy="0 0 0" xyz="0 0 0"/>
      <geometry>
        <mesh filename="file:///home/RAI_65011278/IsaacLab/source/isaaclab_assets/data/Hanu/LegV5_URDF_Export_description/meshes/base_link.stl" scale="0.001 0.001 0.001"/>
      </geometry>
      <material name="silver"/>
    </visual>
    <collision>
      <origin rpy="0 0 0" xyz="0 0 0"/>
      <geometry>
        <mesh filename="file:///home/RAI_65011278/IsaacLab/source/isaaclab_assets/data/Hanu/LegV5_URDF_Export_description/meshes/base_link.stl" scale="0.001 0.001 0.001"/>
      </geometry>
    </collision>
  </link>
  <link name="R1_Hip_1_1">
    <inertial>
      <origin rpy="0 0 0" xyz="1.3761696063263607e-07 -0.06270511666960854 -0.018720220186544095"/>
      <mass value="1.1175978635549133"/>
      <inertia ixx="0.001783" ixy="-0.0" ixz="-0.0" iyy="0.001237" iyz="-0.000107" izz="0.002235"/>
    </inertial>
    <visual>
      <origin rpy="0 0 0" xyz="0.02499 -0.246154 -0.008627"/>
      <geometry>
        <mesh filename="file:///home/RAI_65011278/IsaacLab/source/isaaclab_assets/data/Hanu/LegV5_URDF_Export_description/meshes/R1_Hip_1_1.stl" scale="0.001 0.001 0.001"/>
      </geometry>
      <material name="silver"/>
    </visual>
    <collision>
      <origin rpy="0 0 0" xyz="0.02499 -0.246154 -0.008627"/>
      <geometry>
        <mesh filename="file:///home/RAI_65011278/IsaacLab/source/isaaclab_assets/data/Hanu/LegV5_URDF_Export_description/meshes/R1_Hip_1_1.stl" scale="0.001 0.001 0.001"/>
      </geometry>
    </collision>
  </link>
  <link name="L1_Hip_1_1">
    <inertial>
      <origin rpy="0 0 0" xyz="1.2625891696038671e-07 -0.06270511666960871 -0.01872022627146124"/>
      <mass value="1.1175978635549138"/>
      <inertia ixx="0.001783" ixy="-0.0" ixz="-0.0" iyy="0.001237" iyz="-0.000107" izz="0.002235"/>
    </inertial>
    <visual>
      <origin rpy="0 0 0" xyz="-0.17501 -0.246154 -0.008627"/>
      <geometry>
        <mesh filename="file:///home/RAI_65011278/IsaacLab/source/isaaclab_assets/data/Hanu/LegV5_URDF_Export_description/meshes/L1_Hip_1_1.stl" scale="0.001 0.001 0.001"/>
      </geometry>
      <material name="silver"/>
    </visual>
    <collision>
      <origin rpy="0 0 0" xyz="-0.17501 -0.246154 -0.008627"/>
      <geometry>
        <mesh filename="file:///home/RAI_65011278/IsaacLab/source/isaaclab_assets/data/Hanu/LegV5_URDF_Export_description/meshes/L1_Hip_1_1.stl" scale="0.001 0.001 0.001"/>
      </geometry>
    </collision>
  </link>
  <link name="R2_Hip_1_1">
    <inertial>
      <origin rpy="0 0 0" xyz="0.00036754746932314217 1.62839575765239e-05 0.05987142312032229"/>
      <mass value="1.1890709317590487"/>
      <inertia ixx="0.002374" ixy="0.0" ixz="-5e-06" iyy="0.001777" iyz="1e-06" izz="0.001317"/>
    </inertial>
    <visual>
      <origin rpy="0 0 0" xyz="0.02499 -0.170254 -0.013127"/>
      <geometry>
        <mesh filename="file:///home/RAI_65011278/IsaacLab/source/isaaclab_assets/data/Hanu/LegV5_URDF_Export_description/meshes/R2_Hip_1_1.stl" scale="0.001 0.001 0.001"/>
      </geometry>
      <material name="silver"/>
    </visual>
    <collision>
      <origin rpy="0 0 0" xyz="0.02499 -0.170254 -0.013127"/>
      <geometry>
        <mesh filename="file:///home/RAI_65011278/IsaacLab/source/isaaclab_assets/data/Hanu/LegV5_URDF_Export_description/meshes/R2_Hip_1_1.stl" scale="0.001 0.001 0.001"/>
      </geometry>
    </collision>
  </link>
  <link name="L2_Hip_1_1">
    <inertial>
      <origin rpy="0 0 0" xyz="-0.00036754895168072954 1.6710050126766962e-05 0.059871151672761344"/>
      <mass value="1.1890709317590757"/>
      <inertia ixx="0.002374" ixy="-0.0" ixz="5e-06" iyy="0.001777" iyz="1e-06" izz="0.001317"/>
    </inertial>
    <visual>
      <origin rpy="0 0 0" xyz="-0.17501 -0.170254 -0.013127"/>
      <geometry>
        <mesh filename="file:///home/RAI_65011278/IsaacLab/source/isaaclab_assets/data/Hanu/LegV5_URDF_Export_description/meshes/L2_Hip_1_1.stl" scale="0.001 0.001 0.001"/>
      </geometry>
      <material name="silver"/>
    </visual>
    <collision>
      <origin rpy="0 0 0" xyz="-0.17501 -0.170254 -0.013127"/>
      <geometry>
        <mesh filename="file:///home/RAI_65011278/IsaacLab/source/isaaclab_assets/data/Hanu/LegV5_URDF_Export_description/meshes/L2_Hip_1_1.stl" scale="0.001 0.001 0.001"/>
      </geometry>
    </collision>
  </link>
  <link name="R3_Upper_1_1">
    <inertial>
      <origin rpy="0 0 0" xyz="0.03040527105175731 -0.128717095563938 -0.0007195490236300284"/>
      <mass value="1.6879597584923065"/>
      <inertia ixx="0.021276" ixy="-0.000421" ixz="-8e-06" iyy="0.003585" iyz="0.00013" izz="0.022302"/>
    </inertial>
    <visual>
      <origin rpy="0 0 0" xyz="0.04714 -0.170254 -0.085427"/>
      <geometry>
        <mesh filename="file:///home/RAI_65011278/IsaacLab/source/isaaclab_assets/data/Hanu/LegV5_URDF_Export_description/meshes/R3_Upper_1_1.stl" scale="0.001 0.001 0.001"/>
      </geometry>
      <material name="silver"/>
    </visual>
    <collision>
      <origin rpy="0 0 0" xyz="0.04714 -0.170254 -0.085427"/>
      <geometry>
        <mesh filename="file:///home/RAI_65011278/IsaacLab/source/isaaclab_assets/data/Hanu/LegV5_URDF_Export_description/meshes/R3_Upper_1_1.stl" scale="0.001 0.001 0.001"/>
      </geometry>
    </collision>
  </link>
  <link name="L3_Upper_1_1">
    <inertial>
      <origin rpy="0 0 0" xyz="-0.030405018568597092 -0.12871706146449466 -0.0007195310455429677"/>
      <mass value="1.687960549779457"/>
      <inertia ixx="0.021276" ixy="0.000421" ixz="8e-06" iyy="0.003585" iyz="0.00013" izz="0.022302"/>
    </inertial>
    <visual>
      <origin rpy="0 0 0" xyz="-0.19716 -0.170254 -0.085427"/>
      <geometry>
        <mesh filename="file:///home/RAI_65011278/IsaacLab/source/isaaclab_assets/data/Hanu/LegV5_URDF_Export_description/meshes/L3_Upper_1_1.stl" scale="0.001 0.001 0.001"/>
      </geometry>
      <material name="silver"/>
    </visual>
    <collision>
      <origin rpy="0 0 0" xyz="-0.19716 -0.170254 -0.085427"/>
      <geometry>
        <mesh filename="file:///home/RAI_65011278/IsaacLab/source/isaaclab_assets/data/Hanu/LegV5_URDF_Export_description/meshes/L3_Upper_1_1.stl" scale="0.001 0.001 0.001"/>
      </geometry>
    </collision>
  </link>
  <link name="R4_Lower_1_1">
    <inertial>
      <origin rpy="0 0 0" xyz="0.025525566291602977 -0.10247568362035005 -0.0036059311817167733"/>
      <mass value="3.02851855817208"/>
      <inertia ixx="0.02805" ixy="0.000231" ixz="-4.3e-05" iyy="0.003367" iyz="-0.000156" izz="0.027717"/>
    </inertial>
    <visual>
      <origin rpy="0 0 0" xyz="0.04714 0.109745 -0.085975"/>
      <geometry>
        <mesh filename="file:///home/RAI_65011278/IsaacLab/source/isaaclab_assets/data/Hanu/LegV5_URDF_Export_description/meshes/R4_Lower_1_1.stl" scale="0.001 0.001 0.001"/>
      </geometry>
      <material name="silver"/>
    </visual>
    <collision>
      <origin rpy="0 0 0" xyz="0.04714 0.109745 -0.085975"/>
      <geometry>
        <mesh filename="file:///home/RAI_65011278/IsaacLab/source/isaaclab_assets/data/Hanu/LegV5_URDF_Export_description/meshes/R4_Lower_1_1.stl" scale="0.001 0.001 0.001"/>
      </geometry>
    </collision>
  </link>
  <link name="L4_Lower_1_1">
    <inertial>
      <origin rpy="0 0 0" xyz="-0.02552530232546063 -0.1024756379659899 -0.0036060843552161576"/>
      <mass value="3.0285185588195533"/>
      <inertia ixx="0.02805" ixy="-0.000231" ixz="4.3e-05" iyy="0.003367" iyz="-0.000156" izz="0.027717"/>
    </inertial>
    <visual>
      <origin rpy="0 0 0" xyz="-0.19716 0.109745 -0.085975"/>
      <geometry>
        <mesh filename="file:///home/RAI_65011278/IsaacLab/source/isaaclab_assets/data/Hanu/LegV5_URDF_Export_description/meshes/L4_Lower_1_1.stl" scale="0.001 0.001 0.001"/>
      </geometry>
      <material name="silver"/>
    </visual>
    <collision>
      <origin rpy="0 0 0" xyz="-0.19716 0.109745 -0.085975"/>
      <geometry>
        <mesh filename="file:///home/RAI_65011278/IsaacLab/source/isaaclab_assets/data/Hanu/LegV5_URDF_Export_description/meshes/L4_Lower_1_1.stl" scale="0.001 0.001 0.001"/>
      </geometry>
    </collision>
  </link>
  <link name="R5_Knee_Roll_1_1">
    <inertial>
      <origin rpy="0 0 0" xyz="7.0401173450883314e-06 -2.623983029387267e-06 -0.011740728528397346"/>
      <mass value="0.08677115220458247"/>
      <inertia ixx="1.2e-05" ixy="-0.0" ixz="-0.0" iyy="3.2e-05" iyz="-0.0" izz="3.6e-05"/>
    </inertial>
    <visual>
      <origin rpy="0 0 0" xyz="0.024914 0.227136 -0.049568"/>
      <geometry>
        <mesh filename="file:///home/RAI_65011278/IsaacLab/source/isaaclab_assets/data/Hanu/LegV5_URDF_Export_description/meshes/R5_Knee_Roll_1_1.stl" scale="0.001 0.001 0.001"/>
      </geometry>
      <material name="silver"/>
    </visual>
    <collision>
      <origin rpy="0 0 0" xyz="0.024914 0.227136 -0.049568"/>
      <geometry>
        <mesh filename="file:///home/RAI_65011278/IsaacLab/source/isaaclab_assets/data/Hanu/LegV5_URDF_Export_description/meshes/R5_Knee_Roll_1_1.stl" scale="0.001 0.001 0.001"/>
      </geometry>
    </collision>
  </link>
  <link name="L5_Knee_Roll_1_1">
    <inertial>
      <origin rpy="0 0 0" xyz="0.0020252080122286353 4.244201478653675e-06 -0.011067657148335235"/>
      <mass value="0.08167256846820599"/>
      <inertia ixx="1.1e-05" ixy="-0.0" ixz="2e-06" iyy="2.6e-05" iyz="0.0" izz="3e-05"/>
    </inertial>
    <visual>
      <origin rpy="0 0 0" xyz="-0.174934 0.227136 -0.049567"/>
      <geometry>
        <mesh filename="file:///home/RAI_65011278/IsaacLab/source/isaaclab_assets/data/Hanu/LegV5_URDF_Export_description/meshes/L5_Knee_Roll_1_1.stl" scale="0.001 0.001 0.001"/>
      </geometry>
      <material name="silver"/>
    </visual>
    <collision>
      <origin rpy="0 0 0" xyz="-0.174934 0.227136 -0.049567"/>
      <geometry>
        <mesh filename="file:///home/RAI_65011278/IsaacLab/source/isaaclab_assets/data/Hanu/LegV5_URDF_Export_description/meshes/L5_Knee_Roll_1_1.stl" scale="0.001 0.001 0.001"/>
      </geometry>
    </collision>
  </link>
  <link name="L6_U_Joint_1_1">
    <inertial>
      <origin rpy="0 0 0" xyz="3.3628228043175445e-05 -4.913333608858039e-07 3.3123368148188503e-05"/>
      <mass value="0.5637271012396396"/>
      <inertia ixx="0.00023" ixy="0.0" ixz="0.0" iyy="0.000413" iyz="0.0" izz="0.00023"/>
    </inertial>
    <visual>
      <origin rpy="0 0 0" xyz="-0.17491 0.422829 -0.085765"/>
      <geometry>
        <mesh filename="file:///home/RAI_65011278/IsaacLab/source/isaaclab_assets/data/Hanu/LegV5_URDF_Export_description/meshes/L6_U_Joint_1_1.stl" scale="0.001 0.001 0.001"/>
      </geometry>
      <material name="silver"/>
    </visual>
    <collision>
      <origin rpy="0 0 0" xyz="-0.17491 0.422829 -0.085765"/>
      <geometry>
        <mesh filename="file:///home/RAI_65011278/IsaacLab/source/isaaclab_assets/data/Hanu/LegV5_URDF_Export_description/meshes/L6_U_Joint_1_1.stl" scale="0.001 0.001 0.001"/>
      </geometry>
    </collision>
  </link>
  <link name="R11_Knee_Pitch_1_1">
    <inertial>
      <origin rpy="0 0 0" xyz="-0.005234219344499885 0.014252017914658577 -0.020131528737159343"/>
      <mass value="0.053559761574202155"/>
      <inertia ixx="3.6e-05" ixy="-2e-06" ixz="2e-06" iyy="2.5e-05" iyz="1.4e-05" izz="1.5e-05"/>
    </inertial>
    <visual>
      <origin rpy="0 0 0" xyz="0.03494 0.334926 -0.086663"/>
      <geometry>
        <mesh filename="file:///home/RAI_65011278/IsaacLab/source/isaaclab_assets/data/Hanu/LegV5_URDF_Export_description/meshes/R11_Knee_Pitch_1_1.stl" scale="0.001 0.001 0.001"/>
      </geometry>
      <material name="silver"/>
    </visual>
    <collision>
      <origin rpy="0 0 0" xyz="0.03494 0.334926 -0.086663"/>
      <geometry>
        <mesh filename="file:///home/RAI_65011278/IsaacLab/source/isaaclab_assets/data/Hanu/LegV5_URDF_Export_description/meshes/R11_Knee_Pitch_1_1.stl" scale="0.001 0.001 0.001"/>
      </geometry>
    </collision>
  </link>
  <link name="R13_Foot_1_1">
    <inertial>
      <origin rpy="0 0 0" xyz="4.3798449897023556e-05 -0.095378655368492 -0.014163781518886642"/>
      <mass value="3.846169695262029"/>
      <inertia ixx="0.015725" ixy="4e-06" ixz="-5e-06" iyy="0.015456" iyz="0.001966" izz="0.004608"/>
    </inertial>
    <visual>
      <origin rpy="0 0 0" xyz="0.02489 0.422829 -0.126615"/>
      <geometry>
        <mesh filename="file:///home/RAI_65011278/IsaacLab/source/isaaclab_assets/data/Hanu/LegV5_URDF_Export_description/meshes/R13_Foot_1_1.stl" scale="0.001 0.001 0.001"/>
      </geometry>
      <material name="silver"/>
    </visual>
    <collision>
      <origin rpy="0 0 0" xyz="0.02489 0.422829 -0.126615"/>
      <geometry>
        <mesh filename="file:///home/RAI_65011278/IsaacLab/source/isaaclab_assets/data/Hanu/LegV5_URDF_Export_description/meshes/R13_Foot_1_1.stl" scale="0.001 0.001 0.001"/>
      </geometry>
    </collision>
  </link>
  <link name="L11_Knee_Pitch_1_1">
    <inertial>
      <origin rpy="0 0 0" xyz="0.005234782632497714 0.014241824235705025 -0.02017198170833144"/>
      <mass value="0.05355975682020973"/>
      <inertia ixx="3.6e-05" ixy="2e-06" ixz="-2e-06" iyy="2.5e-05" iyz="1.4e-05" izz="1.5e-05"/>
    </inertial>
    <visual>
      <origin rpy="0 0 0" xyz="-0.18496 0.334926 -0.086663"/>
      <geometry>
        <mesh filename="file:///home/RAI_65011278/IsaacLab/source/isaaclab_assets/data/Hanu/LegV5_URDF_Export_description/meshes/L11_Knee_Pitch_1_1.stl" scale="0.001 0.001 0.001"/>
      </geometry>
      <material name="silver"/>
    </visual>
    <collision>
      <origin rpy="0 0 0" xyz="-0.18496 0.334926 -0.086663"/>
      <geometry>
        <mesh filename="file:///home/RAI_65011278/IsaacLab/source/isaaclab_assets/data/Hanu/LegV5_URDF_Export_description/meshes/L11_Knee_Pitch_1_1.stl" scale="0.001 0.001 0.001"/>
      </geometry>
    </collision>
  </link>
  <link name="L13_Foot_1_1">
    <inertial>
      <origin rpy="0 0 0" xyz="4.378709132391023e-05 -0.09537865536851142 -0.01416378760380857"/>
      <mass value="3.846169695262029"/>
      <inertia ixx="0.015725" ixy="4e-06" ixz="-5e-06" iyy="0.015456" iyz="0.001966" izz="0.004608"/>
    </inertial>
    <visual>
      <origin rpy="0 0 0" xyz="-0.17491 0.422829 -0.126615"/>
      <geometry>
        <mesh filename="file:///home/RAI_65011278/IsaacLab/source/isaaclab_assets/data/Hanu/LegV5_URDF_Export_description/meshes/L13_Foot_1_1.stl" scale="0.001 0.001 0.001"/>
      </geometry>
      <material name="silver"/>
    </visual>
    <collision>
      <origin rpy="0 0 0" xyz="-0.17491 0.422829 -0.126615"/>
      <geometry>
        <mesh filename="file:///home/RAI_65011278/IsaacLab/source/isaaclab_assets/data/Hanu/LegV5_URDF_Export_description/meshes/L13_Foot_1_1.stl" scale="0.001 0.001 0.001"/>
      </geometry>
    </collision>
  </link>
  <link name="R6_U_Joint_1_1">
    <inertial>
      <origin rpy="0 0 0" xyz="-3.336435262375759e-05 -4.913333380707208e-07 3.312945308048265e-05"/>
      <mass value="0.5637271012396396"/>
      <inertia ixx="0.00023" ixy="0.0" ixz="-0.0" iyy="0.000413" iyz="-0.0" izz="0.00023"/>
    </inertial>
    <visual>
      <origin rpy="0 0 0" xyz="0.02489 0.422829 -0.085765"/>
      <geometry>
        <mesh filename="file:///home/RAI_65011278/IsaacLab/source/isaaclab_assets/data/Hanu/LegV5_URDF_Export_description/meshes/R6_U_Joint_1_1.stl" scale="0.001 0.001 0.001"/>
      </geometry>
      <material name="silver"/>
    </visual>
    <collision>
      <origin rpy="0 0 0" xyz="0.02489 0.422829 -0.085765"/>
      <geometry>
        <mesh filename="file:///home/RAI_65011278/IsaacLab/source/isaaclab_assets/data/Hanu/LegV5_URDF_Export_description/meshes/R6_U_Joint_1_1.stl" scale="0.001 0.001 0.001"/>
      </geometry>
    </collision>
  </link>
  <joint name="base_to_R1" type="revolute">
    <origin rpy="0 0 0" xyz="-0.02499 0.246154 0.008627"/>
    <parent link="base_link"/>
    <child link="R1_Hip_1_1"/>
    <axis xyz="-0.0 1.0 -0.0"/>
    <limit effort="32" lower="-3.316126" upper="0.174533" velocity="3.7699"/>
  </joint>
  <joint name="base_to_L1" type="revolute">
    <origin rpy="0 0 0" xyz="0.17501 0.246154 0.008627"/>
    <parent link="base_link"/>
    <child link="L1_Hip_1_1"/>
    <axis xyz="-0.0 1.0 0.0"/>
    <limit effort="32" lower="-0.174533" upper="3.316126" velocity="3.7699"/>
  </joint>
  <joint name="R1_to_R2_Rev" type="revolute">
    <origin rpy="0 0 0" xyz="0.0 -0.0759 0.0045"/>
    <parent link="R1_Hip_1_1"/>
    <child link="R2_Hip_1_1"/>
    <axis xyz="0.0 -0.0 1.0"/>
    <limit effort="72" lower="-1.832596" upper="0.087266" velocity="13.6136"/>
  </joint>
  <joint name="L1_to_L2_Rev" type="revolute">
    <origin rpy="0 0 0" xyz="0.0 -0.0759 0.0045"/>
    <parent link="L1_Hip_1_1"/>
    <child link="L2_Hip_1_1"/>
    <axis xyz="-0.0 0.0 -1.0"/>
    <limit effort="72" lower="-1.832596" upper="0.087266" velocity="13.6136"/>
  </joint>
  <joint name="R2_to_R3_Rev" type="continuous">
    <origin rpy="0 0 0" xyz="-0.02215 0.0 0.0723"/>
    <parent link="R2_Hip_1_1"/>
    <child link="R3_Upper_1_1"/>
    <axis xyz="-1.0 -0.0 0.0"/>
    <limit effort="72" lower="-0.26" upper="2.1" velocity="13.6136"/>
  </joint>
  <joint name="L2_to_L3_Rev" type="continuous">
    <origin rpy="0 0 0" xyz="0.02215 0.0 0.0723"/>
    <parent link="L2_Hip_1_1"/>
    <child link="L3_Upper_1_1"/>
    <axis xyz="1.0 0.0 -0.0"/>
    <limit effort="72" lower="-2.1" upper="0.26" velocity="13.6136"/>
  </joint>
  <joint name="R3_to_R4_Rev" type="revolute">
    <origin rpy="0 0 0" xyz="0.0 -0.279999 0.000548"/>
    <parent link="R3_Upper_1_1"/>
    <child link="R4_Lower_1_1"/>
    <axis xyz="1.0 0.0 0.0"/>
    <limit effort="72" lower="-1.919862" upper="1.919862" velocity="13.6136"/>
  </joint>
  <joint name="L3_to_L4_Rev" type="revolute">
    <origin rpy="0 0 0" xyz="0.0 -0.279999 0.000548"/>
    <parent link="L3_Upper_1_1"/>
    <child link="L4_Lower_1_1"/>
    <axis xyz="-1.0 0.0 0.0"/>
    <limit effort="72" lower="-1.919862" upper="1.919862" velocity="13.6136"/>
  </joint>
  <joint name="R4_to_R5_Rev" type="revolute">
    <origin rpy="0 0 0" xyz="0.022226 -0.117391 -0.036407"/>
    <parent link="R4_Lower_1_1"/>
    <child link="R5_Knee_Roll_1_1"/>
    <axis xyz="-0.0 0.0 1.0"/>
    <limit effort="48" lower="-0.523599" upper="0.523599" velocity="4.1888"/>
    <mimic joint="R6_to_R13_Rev" multiplier="-1.0" offset="0" />
  </joint>
  <joint name="L4_to_L5_Rev" type="revolute">
    <origin rpy="0 0 0" xyz="-0.022226 -0.117391 -0.036408"/>
    <parent link="L4_Lower_1_1"/>
    <child link="L5_Knee_Roll_1_1"/>
    <axis xyz="-0.0 0.0 -1.0"/>
    <limit effort="48" lower="-0.523599" upper="0.523599" velocity="4.1888"/>
    <mimic joint="L6_to_L13_Rev" lower="-1.5" upper="1.5" multiplier="1.0" offset="0" />
  </joint>
  <joint name="L4_to_L6_Rev" type="revolute">
    <origin rpy="0 0 0" xyz="-0.02225 -0.313084 -0.00021"/>
    <parent link="L4_Lower_1_1"/>
    <child link="L6_U_Joint_1_1"/>
    <axis xyz="1.0 -0.0 -0.0"/>
    <limit effort="32" lower="-0.174533" upper="0.523599" velocity="3.7699"/>
  </joint>
  <joint name="R4_to_R11_Rev" type="continuous">
    <origin rpy="0 0 0" xyz="0.0122 -0.225181 0.000688"/>
    <parent link="R4_Lower_1_1"/>
    <child link="R11_Knee_Pitch_1_1"/>
    <axis xyz="-1.0 -0.0 -0.0"/>
    <limit effort="32" velocity="3.7699"/>
    <mimic joint="R4_to_R6_Rev" multiplier="1.0" offset="0" />
  </joint>
  <joint name="R6_to_R13_Rev" type="continuous">
    <origin rpy="0 0 0" xyz="0.0 0.0 0.04085"/>
    <parent link="R6_U_Joint_1_1"/>
    <child link="R13_Foot_1_1"/>
    <axis xyz="0.0 0.0 -1.0"/>
    <limit effort="48" lower="-1.5" upper="1.5" velocity="4.1888"/>
  </joint>
  <joint name="L4_to_L11_Rev" type="continuous">
    <origin rpy="0 0 0" xyz="-0.0122 -0.225181 0.000688"/>
    <parent link="L4_Lower_1_1"/>
    <child link="L11_Knee_Pitch_1_1"/>
    <axis xyz="-1.0 0.0 0.0"/>
    <limit effort="32" velocity="3.7699"/>
    <mimic joint="L4_to_L6_Rev" multiplier="-1.0" offset="0" />
  </joint>
  <joint name="L6_to_L13_Rev" type="continuous">
    <origin rpy="0 0 0" xyz="0.0 0.0 0.04085"/>
    <parent link="L6_U_Joint_1_1"/>
    <child link="L13_Foot_1_1"/>
    <axis xyz="-0.0 0.0 -1.0"/>
    <limit effort="48" velocity="4.1888"/>
  </joint>
  <joint name="R4_to_R6_Rev" type="revolute">
    <origin rpy="0 0 0" xyz="0.02225 -0.313084 -0.00021"/>
    <parent link="R4_Lower_1_1"/>
    <child link="R6_U_Joint_1_1"/>
    <axis xyz="-1.0 0.0 -0.0"/>
    <limit effort="32" lower="-0.523599" upper="0.174533" velocity="3.7699"/>
  </joint>
</robot>
